Workbook

Sheet Rekap Nilai Cek
A1: No | B1: Nama Pengukuran | C1: Jumlah Titik | D1: Mean Latitude | E1: Mean Longitude | F1: Mean Height (m) | G1: SD Latitude | H1: SD Longitude | I1: SD Height (m) | J1: RMSE Latitude | K1: RMSE Longitude | L1: RMSE Height (m) | M1: Referensi Trimble | N1: Mean Trimble Latitude | O1: Mean Trimble Longitude | P1: Mean Trimble Height (m) | Q1: RMSE Latitude vs Trimble | R1: RMSE Longitude vs Trimble | S1: RMSE Height vs Trimble (m)
A2: 1 | B2: BM1Day1 | C2: =BM1Day1!I2 -> 3849 | D2: =BM1Day1!I3 -> -7.1600166 | E2: =BM1Day1!I4 -> 112.78153 | F2: =BM1Day1!I5 -> 58.864984 | G2: =BM1Day1!I6 -> 3.6598502e-06 | H2: =BM1Day1!I7 -> 2.4471324e-06 | I2: =BM1Day1!I8 -> 0.67904702 | J2: =BM1Day1!I9 -> 3.6593748e-06 | K2: =BM1Day1!I10 -> 2.4468145e-06 | L2: =BM1Day1!I11 -> 0.6789588 | M2: =BM1Day1!I12 -> BM1 | N2: =BM1Day1!I13 -> -7.1600167 | O2: =BM1Day1!I14 -> 112.78153 | P2: =BM1Day1!I15 -> 58.875071 | Q2: =BM1Day1!I16 -> 3.6600662e-06 | R2: =BM1Day1!I17 -> 2.4469003e-06 | S2: =BM1Day1!I18 -> 0.67903373
A3: 2 | B3: BM2Day1 | C3: =BM2Day1!I2 -> 3918 | D3: =BM2Day1!I3 -> -7.1597329 | E3: =BM2Day1!I4 -> 112.78237 | F3: =BM2Day1!I5 -> 57.447582 | G3: =BM2Day1!I6 -> 7.5746088e-06 | H3: =BM2Day1!I7 -> 4.0334855e-06 | I3: =BM2Day1!I8 -> 1.3018437 | J3: =BM2Day1!I9 -> 7.5736421e-06 | K3: =BM2Day1!I10 -> 4.0329707e-06 | L3: =BM2Day1!I11 -> 1.3016775 | M3: =BM2Day1!I12 -> BM2 | N3: =BM2Day1!I13 -> -7.1597329 | O3: =BM2Day1!I14 -> 112.78237 | P3: =BM2Day1!I15 -> 57.447582 | Q3: =BM2Day1!I16 -> 7.5736421e-06 | R3: =BM2Day1!I17 -> 4.0329707e-06 | S3: =BM2Day1!I18 -> 1.3016775
A4: 3 | B4: BM3Day1 | C4: =BM3Day1!I2 -> 1135 | D4: =BM3Day1!I3 -> -7.153403 | E4: =BM3Day1!I4 -> 112.78357 | F4: =BM3Day1!I5 -> 69.943059 | G4: =BM3Day1!I6 -> 2.0636977e-06 | H4: =BM3Day1!I7 -> 1.6967384e-06 | I4: =BM3Day1!I8 -> 0.12887566 | J4: =BM3Day1!I9 -> 2.0627883e-06 | K4: =BM3Day1!I10 -> 1.6959908e-06 | L4: =BM3Day1!I11 -> 0.12881887 | M4: =BM3Day1!I12 -> BM3 | N4: =BM3Day1!I13 -> -7.153403 | O4: =BM3Day1!I14 -> 112.78357 | P4: =BM3Day1!I15 -> 69.943059 | Q4: =BM3Day1!I16 -> 2.0627883e-06 | R4: =BM3Day1!I17 -> 1.6959908e-06 | S4: =BM3Day1!I18 -> 0.12881887
A5: 4 | B5: BM4Day1 | C5: 3753 | D5: -7.1535853 | E5: 112.78383 | F5: 17.9377 | G5: 1.9098188e-06 | H5: 8.6745256e-07 | I5: 0.66291309 | J5: 1.9095644e-06 | K5: 8.6733699e-07 | L5: 0.66282476 | M5: BM4 | N5: -7.1535853 | O5: 112.78383 | P5: 17.9377 | Q5: 1.9095644e-06 | R5: 8.6733699e-07 | S5: 0.66282476
A6: 5 | B6: BM1Day2 | C6: =BM1Day2!I2 -> 1501 | D6: =BM1Day2!I3 -> -7.1600167 | E6: =BM1Day2!I4 -> 112.78153 | F6: =BM1Day2!I5 -> 58.875071 | G6: =BM1Day2!I6 -> 6.6684755e-07 | H6: =BM1Day2!I7 -> 3.5003151e-07 | I6: =BM1Day2!I8 -> 0.066461923 | J6: =BM1Day2!I9 -> 6.6662538e-07 | K6: =BM1Day2!I10 -> 3.4991489e-07 | L6: =BM1Day2!I11 -> 0.06643978 | M6: =BM1Day2!I12 -> BM1 | N6: =BM1Day2!I13 -> -7.1600167 | O6: =BM1Day2!I14 -> 112.78153 | P6: =BM1Day2!I15 -> 58.875071 | Q6: =BM1Day2!I16 -> 6.6662538e-07 | R6: =BM1Day2!I17 -> 3.4991489e-07 | S6: =BM1Day2!I18 -> 0.06643978
A7: 6 | B7: BM2Day2 | C7: =BM2Day2!I2 -> 1085 | D7: =BM2Day2!I3 -> -7.1597329 | E7: =BM2Day2!I4 -> 112.78237 | F7: =BM2Day2!I5 -> 57.447582 | G7: =BM2Day2!I6 -> 1.8432765e-06 | H7: =BM2Day2!I7 -> 1.0932501e-06 | I7: =BM2Day2!I8 -> 0.15509242 | J7: =BM2Day2!I9 -> 1.8424269e-06 | K7: =BM2Day2!I10 -> 1.0927462e-06 | L7: =BM2Day2!I11 -> 0.15502094 | M7: =BM2Day2!I12 -> BM2 | N7: =BM2Day2!I13 -> -7.1597329 | O7: =BM2Day2!I14 -> 112.78237 | P7: =BM2Day2!I15 -> 57.447582 | Q7: =BM2Day2!I16 -> 1.8424269e-06 | R7: =BM2Day2!I17 -> 1.0927462e-06 | S7: =BM2Day2!I18 -> 0.15502094
A8: 7 | B8: BM3Day2 | C8: =BM3Day2!I2 -> 3956 | D8: =BM3Day2!I3 -> -7.153403 | E8: =BM3Day2!I4 -> 112.78357 | F8: =BM3Day2!I5 -> 69.943059 | G8: =BM3Day2!I6 -> 2.1452748e-06 | H8: =BM3Day2!I7 -> 8.5831586e-07 | I8: =BM3Day2!I8 -> 0.14534571 | J8: =BM3Day2!I9 -> 2.1450036e-06 | K8: =BM3Day2!I10 -> 8.5820737e-07 | L8: =BM3Day2!I11 -> 0.14532734 | M8: =BM3Day2!I12 -> BM3 | N8: =BM3Day2!I13 -> -7.153403 | O8: =BM3Day2!I14 -> 112.78357 | P8: =BM3Day2!I15 -> 69.943059 | Q8: =BM3Day2!I16 -> 2.1450036e-06 | R8: =BM3Day2!I17 -> 8.5820737e-07 | S8: =BM3Day2!I18 -> 0.14532734
A9: 8 | B9: BM4Day2 | C9: 3714 | D9: -7.1535853 | E9: 112.78383 | F9: 17.9377 | G9: 6.2875883e-06 | H9: 6.4208352e-06 | I9: 0.71776148 | J9: 6.2867418e-06 | K9: 6.4199707e-06 | L9: 0.71766484 | M9: BM4 | N9: -7.1535853 | O9: 112.78383 | P9: 17.9377 | Q9: 6.2867418e-06 | R9: 6.4199707e-06 | S9: 0.71766484
A10: 9 | B10: BM1Day3 | C10: =BM1Day3!I2 -> 2368 | D10: =BM1Day3!I3 -> -7.1600167 | E10: =BM1Day3!I4 -> 112.78153 | F10: =BM1Day3!I5 -> 58.875071 | G10: =BM1Day3!I6 -> 6.8054075e-07 | H10: =BM1Day3!I7 -> 1.1768247e-06 | I10: =BM1Day3!I8 -> 0.37846817 | J10: =BM1Day3!I9 -> 6.8039704e-07 | K10: =BM1Day3!I10 -> 1.1765762e-06 | L10: =BM1Day3!I11 -> 0.37838825 | M10: =BM1Day3!I12 -> BM1 | N10: =BM1Day3!I13 -> -7.1600167 | O10: =BM1Day3!I14 -> 112.78153 | P10: =BM1Day3!I15 -> 58.875071 | Q10: =BM1Day3!I16 -> 6.8039704e-07 | R10: =BM1Day3!I17 -> 1.1765762e-06 | S10: =BM1Day3!I18 -> 0.37838825
A11: 10 | B11: BM2Day3 | C11: =BM2Day3!I2 -> 3899 | D11: =BM2Day3!I3 -> -7.1597329 | E11: =BM2Day3!I4 -> 112.78237 | F11: =BM2Day3!I5 -> 57.447582 | G11: =BM2Day3!I6 -> 2.4920318e-06 | H11: =BM2Day3!I7 -> 2.5846114e-06 | I11: =BM2Day3!I8 -> 0.25671666 | J11: =BM2Day3!I9 -> 2.4917122e-06 | K11: =BM2Day3!I10 -> 2.5842799e-06 | L11: =BM2Day3!I11 -> 0.25668374 | M11: =BM2Day3!I12 -> BM2 | N11: =BM2Day3!I13 -> -7.1597329 | O11: =BM2Day3!I14 -> 112.78237 | P11: =BM2Day3!I15 -> 57.447582 | Q11: =BM2Day3!I16 -> 2.4917122e-06 | R11: =BM2Day3!I17 -> 2.5842799e-06 | S11: =BM2Day3!I18 -> 0.25668374
A12: 11 | B12: BM3Day3 | C12: =BM3Day3!I2 -> 2273 | D12: =BM3Day3!I3 -> -7.153403 | E12: =BM3Day3!I4 -> 112.78357 | F12: =BM3Day3!I5 -> 69.943059 | G12: =BM3Day3!I6 -> 1.6150735e-06 | H12: =BM3Day3!I7 -> 1.2617565e-06 | I12: =BM3Day3!I8 -> 0.39340443 | J12: =BM3Day3!I9 -> 1.6147182e-06 | K12: =BM3Day3!I10 -> 1.2614789e-06 | L12: =BM3Day3!I11 -> 0.39331788 | M12: =BM3Day3!I12 -> BM3 | N12: =BM3Day3!I13 -> -7.153403 | O12: =BM3Day3!I14 -> 112.78357 | P12: =BM3Day3!I15 -> 69.943059 | Q12: =BM3Day3!I16 -> 1.6147182e-06 | R12: =BM3Day3!I17 -> 1.2614789e-06 | S12: =BM3Day3!I18 -> 0.39331788
A13: 12 | B13: BM4Day3 | C13: 3714 | D13: -7.1535853 | E13: 112.78383 | F13: 17.9377 | G13: 6.2875883e-06 | H13: 6.4208352e-06 | I13: 0.71776148 | J13: 6.2867418e-06 | K13: 6.4199707e-06 | L13: 0.71766484 | M13: BM4 | N13: -7.1535853 | O13: 112.78383 | P13: 17.9377 | Q13: 6.2867418e-06 | R13: 6.4199707e-06 | S13: 0.71766484
A14: 13 | B14: BM1Day4 | C14: =BM1Day4!I2 -> 1881 | D14: =BM1Day4!I3 -> -7.1600167 | E14: =BM1Day4!I4 -> 112.78153 | F14: =BM1Day4!I5 -> 58.875071 | G14: =BM1Day4!I6 -> 1.4418344e-06 | H14: =BM1Day4!I7 -> 9.1803512e-07 | I14: =BM1Day4!I8 -> 0.088330511 | J14: =BM1Day4!I9 -> 1.4414511e-06 | K14: =BM1Day4!I10 -> 9.1779106e-07 | L14: =BM1Day4!I11 -> 0.088307028 | M14: =BM1Day4!I12 -> BM1 | N14: =BM1Day4!I13 -> -7.1600167 | O14: =BM1Day4!I14 -> 112.78153 | P14: =BM1Day4!I15 -> 58.875071 | Q14: =BM1Day4!I16 -> 1.4414511e-06 | R14: =BM1Day4!I17 -> 9.1779106e-07 | S14: =BM1Day4!I18 -> 0.088307028
A15: 14 | B15: BM2Day4 | C15: =BM2Day4!I2 -> 1811 | D15: =BM2Day4!I3 -> -7.1597329 | E15: =BM2Day4!I4 -> 112.78237 | F15: =BM2Day4!I5 -> 57.447582 | G15: =BM2Day4!I6 -> 5.7596435e-08 | H15: =BM2Day4!I7 -> 9.7794733e-08 | I15: =BM2Day4!I8 -> 0.019734547 | J15: =BM2Day4!I9 -> 5.7580531e-08 | K15: =BM2Day4!I10 -> 9.776773e-08 | L15: =BM2Day4!I11 -> 0.019729098 | M15: =BM2Day4!I12 -> BM2 | N15: =BM2Day4!I13 -> -7.1597329 | O15: =BM2Day4!I14 -> 112.78237 | P15: =BM2Day4!I15 -> 57.447582 | Q15: =BM2Day4!I16 -> 5.7580531e-08 | R15: =BM2Day4!I17 -> 9.776773e-08 | S15: =BM2Day4!I18 -> 0.019729098
A16: 15 | B16: BM3Day4 | C16: =BM3Day4!I2 -> 1844 | D16: =BM3Day4!I3 -> -7.153403 | E16: =BM3Day4!I4 -> 112.78357 | F16: =BM3Day4!I5 -> 69.943059 | G16: =BM3Day4!I6 -> 5.2960452e-06 | H16: =BM3Day4!I7 -> 2.5381672e-06 | I16: =BM3Day4!I8 -> 0.76627075 | J16: =BM3Day4!I9 -> 5.294609e-06 | K16: =BM3Day4!I10 -> 2.5374789e-06 | L16: =BM3Day4!I11 -> 0.76606295 | M16: =BM3Day4!I12 -> BM3 | N16: =BM3Day4!I13 -> -7.153403 | O16: =BM3Day4!I14 -> 112.78357 | P16: =BM3Day4!I15 -> 69.943059 | Q16: =BM3Day4!I16 -> 5.294609e-06 | R16: =BM3Day4!I17 -> 2.5374789e-06 | S16: =BM3Day4!I18 -> 0.76606295
A17: 16 | B17: BM4Day4 | C17: 1757 | D17: -7.1535853 | E17: 112.78383 | F17: 17.9377 | G17: 1.4304501e-06 | H17: 1.2087968e-06 | I17: 0.55233561 | J17: 1.430043e-06 | K17: 1.2084527e-06 | L17: 0.55217841 | M17: BM4 | N17: -7.1535853 | O17: 112.78383 | P17: 17.9377 | Q17: 1.430043e-06 | R17: 1.2084527e-06 | S17: 0.55217841

Sheet Rekap Formula
A1: No | B1: Nama Pengukuran | C1: Jumlah Titik | D1: Mean Latitude | E1: Mean Longitude | F1: Mean Height (m) | G1: SD Latitude | H1: SD Longitude | I1: SD Height (m) | J1: RMSE Latitude | K1: RMSE Longitude | L1: RMSE Height (m) | M1: Referensi Trimble | N1: Mean Trimble Latitude | O1: Mean Trimble Longitude | P1: Mean Trimble Height (m) | Q1: RMSE Latitude vs Trimble | R1: RMSE Longitude vs Trimble | S1: RMSE Height vs Trimble (m)
A2: 1 | B2: BM1Day1 | C2: =BM1Day1!I2 -> 3849 | D2: =BM1Day1!I3 -> -7.1600166 | E2: =BM1Day1!I4 -> 112.78153 | F2: =BM1Day1!I5 -> 58.864984 | G2: =BM1Day1!I6 -> 3.6598502e-06 | H2: =BM1Day1!I7 -> 2.4471324e-06 | I2: =BM1Day1!I8 -> 0.67904702 | J2: =BM1Day1!I9 -> 3.6593748e-06 | K2: =BM1Day1!I10 -> 2.4468145e-06 | L2: =BM1Day1!I11 -> 0.6789588 | M2: =BM1Day1!I12 -> BM1 | N2: =BM1Day1!I13 -> -7.1600167 | O2: =BM1Day1!I14 -> 112.78153 | P2: =BM1Day1!I15 -> 58.875071 | Q2: =BM1Day1!I16 -> 3.6600662e-06 | R2: =BM1Day1!I17 -> 2.4469003e-06 | S2: =BM1Day1!I18 -> 0.67903373
A3: 2 | B3: BM2Day1 | C3: =BM2Day1!I2 -> 3918 | D3: =BM2Day1!I3 -> -7.1597329 | E3: =BM2Day1!I4 -> 112.78237 | F3: =BM2Day1!I5 -> 57.447582 | G3: =BM2Day1!I6 -> 7.5746088e-06 | H3: =BM2Day1!I7 -> 4.0334855e-06 | I3: =BM2Day1!I8 -> 1.3018437 | J3: =BM2Day1!I9 -> 7.5736421e-06 | K3: =BM2Day1!I10 -> 4.0329707e-06 | L3: =BM2Day1!I11 -> 1.3016775 | M3: =BM2Day1!I12 -> BM2 | N3: =BM2Day1!I13 -> -7.1597329 | O3: =BM2Day1!I14 -> 112.78237 | P3: =BM2Day1!I15 -> 57.447582 | Q3: =BM2Day1!I16 -> 7.5736421e-06 | R3: =BM2Day1!I17 -> 4.0329707e-06 | S3: =BM2Day1!I18 -> 1.3016775
A4: 3 | B4: BM3Day1 | C4: =BM3Day1!I2 -> 1135 | D4: =BM3Day1!I3 -> -7.153403 | E4: =BM3Day1!I4 -> 112.78357 | F4: =BM3Day1!I5 -> 69.943059 | G4: =BM3Day1!I6 -> 2.0636977e-06 | H4: =BM3Day1!I7 -> 1.6967384e-06 | I4: =BM3Day1!I8 -> 0.12887566 | J4: =BM3Day1!I9 -> 2.0627883e-06 | K4: =BM3Day1!I10 -> 1.6959908e-06 | L4: =BM3Day1!I11 -> 0.12881887 | M4: =BM3Day1!I12 -> BM3 | N4: =BM3Day1!I13 -> -7.153403 | O4: =BM3Day1!I14 -> 112.78357 | P4: =BM3Day1!I15 -> 69.943059 | Q4: =BM3Day1!I16 -> 2.0627883e-06 | R4: =BM3Day1!I17 -> 1.6959908e-06 | S4: =BM3Day1!I18 -> 0.12881887
A5: 4 | B5: BM4Day1 | C5: =BM4Day1!I2 -> 3753 | D5: =BM4Day1!I3 -> -7.1535853 | E5: =BM4Day1!I4 -> 112.78383 | F5: =BM4Day1!I5 -> 17.9377 | G5: =BM4Day1!I6 -> 1.9098188e-06 | H5: =BM4Day1!I7 -> 8.6745256e-07 | I5: =BM4Day1!I8 -> 0.66291309 | J5: =BM4Day1!I9 -> 1.9095644e-06 | K5: =BM4Day1!I10 -> 8.6733699e-07 | L5: =BM4Day1!I11 -> 0.66282476 | M5: =BM4Day1!I12 -> BM4 | N5: =BM4Day1!I13 -> -7.1535853 | O5: =BM4Day1!I14 -> 112.78383 | P5: =BM4Day1!I15 -> 17.9377 | Q5: =BM4Day1!I16 -> 1.9095644e-06 | R5: =BM4Day1!I17 -> 8.6733699e-07 | S5: =BM4Day1!I18 -> 0.66282476
A6: 5 | B6: BM1Day2 | C6: =BM1Day2!I2 -> 1501 | D6: =BM1Day2!I3 -> -7.1600167 | E6: =BM1Day2!I4 -> 112.78153 | F6: =BM1Day2!I5 -> 58.875071 | G6: =BM1Day2!I6 -> 6.6684755e-07 | H6: =BM1Day2!I7 -> 3.5003151e-07 | I6: =BM1Day2!I8 -> 0.066461923 | J6: =BM1Day2!I9 -> 6.6662538e-07 | K6: =BM1Day2!I10 -> 3.4991489e-07 | L6: =BM1Day2!I11 -> 0.06643978 | M6: =BM1Day2!I12 -> BM1 | N6: =BM1Day2!I13 -> -7.1600167 | O6: =BM1Day2!I14 -> 112.78153 | P6: =BM1Day2!I15 -> 58.875071 | Q6: =BM1Day2!I16 -> 6.6662538e-07 | R6: =BM1Day2!I17 -> 3.4991489e-07 | S6: =BM1Day2!I18 -> 0.06643978
A7: 6 | B7: BM2Day2 | C7: =BM2Day2!I2 -> 1085 | D7: =BM2Day2!I3 -> -7.1597329 | E7: =BM2Day2!I4 -> 112.78237 | F7: =BM2Day2!I5 -> 57.447582 | G7: =BM2Day2!I6 -> 1.8432765e-06 | H7: =BM2Day2!I7 -> 1.0932501e-06 | I7: =BM2Day2!I8 -> 0.15509242 | J7: =BM2Day2!I9 -> 1.8424269e-06 | K7: =BM2Day2!I10 -> 1.0927462e-06 | L7: =BM2Day2!I11 -> 0.15502094 | M7: =BM2Day2!I12 -> BM2 | N7: =BM2Day2!I13 -> -7.1597329 | O7: =BM2Day2!I14 -> 112.78237 | P7: =BM2Day2!I15 -> 57.447582 | Q7: =BM2Day2!I16 -> 1.8424269e-06 | R7: =BM2Day2!I17 -> 1.0927462e-06 | S7: =BM2Day2!I18 -> 0.15502094
A8: 7 | B8: BM3Day2 | C8: =BM3Day2!I2 -> 3956 | D8: =BM3Day2!I3 -> -7.153403 | E8: =BM3Day2!I4 -> 112.78357 | F8: =BM3Day2!I5 -> 69.943059 | G8: =BM3Day2!I6 -> 2.1452748e-06 | H8: =BM3Day2!I7 -> 8.5831586e-07 | I8: =BM3Day2!I8 -> 0.14534571 | J8: =BM3Day2!I9 -> 2.1450036e-06 | K8: =BM3Day2!I10 -> 8.5820737e-07 | L8: =BM3Day2!I11 -> 0.14532734 | M8: =BM3Day2!I12 -> BM3 | N8: =BM3Day2!I13 -> -7.153403 | O8: =BM3Day2!I14 -> 112.78357 | P8: =BM3Day2!I15 -> 69.943059 | Q8: =BM3Day2!I16 -> 2.1450036e-06 | R8: =BM3Day2!I17 -> 8.5820737e-07 | S8: =BM3Day2!I18 -> 0.14532734
A9: 8 | B9: BM4Day2 | C9: =BM4Day2!I2 -> 3714 | D9: =BM4Day2!I3 -> -7.1535853 | E9: =BM4Day2!I4 -> 112.78383 | F9: =BM4Day2!I5 -> 17.9377 | G9: =BM4Day2!I6 -> 6.2875883e-06 | H9: =BM4Day2!I7 -> 6.4208352e-06 | I9: =BM4Day2!I8 -> 0.71776148 | J9: =BM4Day2!I9 -> 6.2867418e-06 | K9: =BM4Day2!I10 -> 6.4199707e-06 | L9: =BM4Day2!I11 -> 0.71766484 | M9: =BM4Day2!I12 -> BM4 | N9: =BM4Day2!I13 -> -7.1535853 | O9: =BM4Day2!I14 -> 112.78383 | P9: =BM4Day2!I15 -> 17.9377 | Q9: =BM4Day2!I16 -> 6.2867418e-06 | R9: =BM4Day2!I17 -> 6.4199707e-06 | S9: =BM4Day2!I18 -> 0.71766484
A10: 9 | B10: BM1Day3 | C10: =BM1Day3!I2 -> 2368 | D10: =BM1Day3!I3 -> -7.1600167 | E10: =BM1Day3!I4 -> 112.78153 | F10: =BM1Day3!I5 -> 58.875071 | G10: =BM1Day3!I6 -> 6.8054075e-07 | H10: =BM1Day3!I7 -> 1.1768247e-06 | I10: =BM1Day3!I8 -> 0.37846817 | J10: =BM1Day3!I9 -> 6.8039704e-07 | K10: =BM1Day3!I10 -> 1.1765762e-06 | L10: =BM1Day3!I11 -> 0.37838825 | M10: =BM1Day3!I12 -> BM1 | N10: =BM1Day3!I13 -> -7.1600167 | O10: =BM1Day3!I14 -> 112.78153 | P10: =BM1Day3!I15 -> 58.875071 | Q10: =BM1Day3!I16 -> 6.8039704e-07 | R10: =BM1Day3!I17 -> 1.1765762e-06 | S10: =BM1Day3!I18 -> 0.37838825
A11: 10 | B11: BM2Day3 | C11: =BM2Day3!I2 -> 3899 | D11: =BM2Day3!I3 -> -7.1597329 | E11: =BM2Day3!I4 -> 112.78237 | F11: =BM2Day3!I5 -> 57.447582 | G11: =BM2Day3!I6 -> 2.4920318e-06 | H11: =BM2Day3!I7 -> 2.5846114e-06 | I11: =BM2Day3!I8 -> 0.25671666 | J11: =BM2Day3!I9 -> 2.4917122e-06 | K11: =BM2Day3!I10 -> 2.5842799e-06 | L11: =BM2Day3!I11 -> 0.25668374 | M11: =BM2Day3!I12 -> BM2 | N11: =BM2Day3!I13 -> -7.1597329 | O11: =BM2Day3!I14 -> 112.78237 | P11: =BM2Day3!I15 -> 57.447582 | Q11: =BM2Day3!I16 -> 2.4917122e-06 | R11: =BM2Day3!I17 -> 2.5842799e-06 | S11: =BM2Day3!I18 -> 0.25668374
A12: 11 | B12: BM3Day3 | C12: =BM3Day3!I2 -> 2273 | D12: =BM3Day3!I3 -> -7.153403 | E12: =BM3Day3!I4 -> 112.78357 | F12: =BM3Day3!I5 -> 69.943059 | G12: =BM3Day3!I6 -> 1.6150735e-06 | H12: =BM3Day3!I7 -> 1.2617565e-06 | I12: =BM3Day3!I8 -> 0.39340443 | J12: =BM3Day3!I9 -> 1.6147182e-06 | K12: =BM3Day3!I10 -> 1.2614789e-06 | L12: =BM3Day3!I11 -> 0.39331788 | M12: =BM3Day3!I12 -> BM3 | N12: =BM3Day3!I13 -> -7.153403 | O12: =BM3Day3!I14 -> 112.78357 | P12: =BM3Day3!I15 -> 69.943059 | Q12: =BM3Day3!I16 -> 1.6147182e-06 | R12: =BM3Day3!I17 -> 1.2614789e-06 | S12: =BM3Day3!I18 -> 0.39331788
A13: 12 | B13: BM4Day3 | C13: =BM4Day3!I2 -> 3714 | D13: =BM4Day3!I3 -> -7.1535853 | E13: =BM4Day3!I4 -> 112.78383 | F13: =BM4Day3!I5 -> 17.9377 | G13: =BM4Day3!I6 -> 6.2875883e-06 | H13: =BM4Day3!I7 -> 6.4208352e-06 | I13: =BM4Day3!I8 -> 0.71776148 | J13: =BM4Day3!I9 -> 6.2867418e-06 | K13: =BM4Day3!I10 -> 6.4199707e-06 | L13: =BM4Day3!I11 -> 0.71766484 | M13: =BM4Day3!I12 -> BM4 | N13: =BM4Day3!I13 -> -7.1535853 | O13: =BM4Day3!I14 -> 112.78383 | P13: =BM4Day3!I15 -> 17.9377 | Q13: =BM4Day3!I16 -> 6.2867418e-06 | R13: =BM4Day3!I17 -> 6.4199707e-06 | S13: =BM4Day3!I18 -> 0.71766484
A14: 13 | B14: BM1Day4 | C14: =BM1Day4!I2 -> 1881 | D14: =BM1Day4!I3 -> -7.1600167 | E14: =BM1Day4!I4 -> 112.78153 | F14: =BM1Day4!I5 -> 58.875071 | G14: =BM1Day4!I6 -> 1.4418344e-06 | H14: =BM1Day4!I7 -> 9.1803512e-07 | I14: =BM1Day4!I8 -> 0.088330511 | J14: =BM1Day4!I9 -> 1.4414511e-06 | K14: =BM1Day4!I10 -> 9.1779106e-07 | L14: =BM1Day4!I11 -> 0.088307028 | M14: =BM1Day4!I12 -> BM1 | N14: =BM1Day4!I13 -> -7.1600167 | O14: =BM1Day4!I14 -> 112.78153 | P14: =BM1Day4!I15 -> 58.875071 | Q14: =BM1Day4!I16 -> 1.4414511e-06 | R14: =BM1Day4!I17 -> 9.1779106e-07 | S14: =BM1Day4!I18 -> 0.088307028
A15: 14 | B15: BM2Day4 | C15: =BM2Day4!I2 -> 1811 | D15: =BM2Day4!I3 -> -7.1597329 | E15: =BM2Day4!I4 -> 112.78237 | F15: =BM2Day4!I5 -> 57.447582 | G15: =BM2Day4!I6 -> 5.7596435e-08 | H15: =BM2Day4!I7 -> 9.7794733e-08 | I15: =BM2Day4!I8 -> 0.019734547 | J15: =BM2Day4!I9 -> 5.7580531e-08 | K15: =BM2Day4!I10 -> 9.776773e-08 | L15: =BM2Day4!I11 -> 0.019729098 | M15: =BM2Day4!I12 -> BM2 | N15: =BM2Day4!I13 -> -7.1597329 | O15: =BM2Day4!I14 -> 112.78237 | P15: =BM2Day4!I15 -> 57.447582 | Q15: =BM2Day4!I16 -> 5.7580531e-08 | R15: =BM2Day4!I17 -> 9.776773e-08 | S15: =BM2Day4!I18 -> 0.019729098
A16: 15 | B16: BM3Day4 | C16: =BM3Day4!I2 -> 1844 | D16: =BM3Day4!I3 -> -7.153403 | E16: =BM3Day4!I4 -> 112.78357 | F16: =BM3Day4!I5 -> 69.943059 | G16: =BM3Day4!I6 -> 5.2960452e-06 | H16: =BM3Day4!I7 -> 2.5381672e-06 | I16: =BM3Day4!I8 -> 0.76627075 | J16: =BM3Day4!I9 -> 5.294609e-06 | K16: =BM3Day4!I10 -> 2.5374789e-06 | L16: =BM3Day4!I11 -> 0.76606295 | M16: =BM3Day4!I12 -> BM3 | N16: =BM3Day4!I13 -> -7.153403 | O16: =BM3Day4!I14 -> 112.78357 | P16: =BM3Day4!I15 -> 69.943059 | Q16: =BM3Day4!I16 -> 5.294609e-06 | R16: =BM3Day4!I17 -> 2.5374789e-06 | S16: =BM3Day4!I18 -> 0.76606295
A17: 16 | B17: BM4Day4 | C17: =BM4Day4!I2 -> 1757 | D17: =BM4Day4!I3 -> -7.1535853 | E17: =BM4Day4!I4 -> 112.78383 | F17: =BM4Day4!I5 -> 17.9377 | G17: =BM4Day4!I6 -> 1.4304501e-06 | H17: =BM4Day4!I7 -> 1.2087968e-06 | I17: =BM4Day4!I8 -> 0.55233561 | J17: =BM4Day4!I9 -> 1.430043e-06 | K17: =BM4Day4!I10 -> 1.2084527e-06 | L17: =BM4Day4!I11 -> 0.55217841 | M17: =BM4Day4!I12 -> BM4 | N17: =BM4Day4!I13 -> -7.1535853 | O17: =BM4Day4!I14 -> 112.78383 | P17: =BM4Day4!I15 -> 17.9377 | Q17: =BM4Day4!I16 -> 1.430043e-06 | R17: =BM4Day4!I17 -> 1.2084527e-06 | S17: =BM4Day4!I18 -> 0.55217841

Sheet Keterangan
A1: Item | B1: Penjelasan
A2: Isi Workbook | B2: Workbook ini memuat 16 sheet data sumber + 2 sheet rekap.
A3: Rekap Nilai Cek | B3: Nilai mean, standar deviasi, dan RMSE yang dihitung dari setiap sheet data.
A4: Rekap Formula | B4: Nilai yang diambil dari formula Excel pada masing-masing sheet data.
A5: Mean | B5: Rata-rata data pada kolom Latitude, Longitude, atau Height.
A6: Standar Deviasi | B6: Menggunakan STDEV.S (standar deviasi sampel).
A7: RMSE | B7: Dihitung terhadap mean masing-masing file, bukan terhadap koordinat referensi eksternal.
A8: Trimble Referensi | B8: BM1 memakai file Trimble BM 1, BM2 memakai file Trimble BM 2, BM3 memakai file Trimble BM 3, dan BM4 memakai file Trimble BM 3 karena file Trimble BM4 belum tersedia.
A9: Mean Trimble | B9: Rata-rata koordinat/height pada file Trimble referensi yang dipakai untuk pembanding.
A10: RMSE vs Trimble | B10: Dihitung sebagai akar rata-rata kuadrat selisih setiap titik pengukuran terhadap mean Trimble referensi pada koordinat yang sama.
A15: Pembaruan BM4 terbaru
A16: BM4 Day 1-Day 4 telah benar-benar diperbarui menggunakan low-cost BM4 terbaru (file dengan akhiran (1)) dan referensi Trimble BM4 terbaru.

Sheet BM1Day1
A1: Tanggal | B1: Waktu (UTC) | C1: Latitude | D1: Longitude | E1: Height (m) | H1: Statistik | I1: Nilai (Formula Excel) | J1: Formula Teks / Catatan
A2: 46047 | B2: 0.24736111 | C2: -7.1600243 | D2: 112.78153 | E2: 60.366525 | H2: Jumlah Titik | I2: =COUNT(C2:C3850) -> 3849 | J2: '=COUNT(C2:C3850)
A3: 46047 | B3: 0.24737269 | C3: -7.1600243 | D3: 112.78153 | E3: 60.364125 | H3: Mean Latitude | I3: =AVERAGE(C2:C3850) -> -7.1600166 | J3: '=AVERAGE(C2:C3850)
A4: 46047 | B4: 0.24738426 | C4: -7.1600243 | D4: 112.78153 | E4: 60.363125 | H4: Mean Longitude | I4: =AVERAGE(D2:D3850) -> 112.78153 | J4: '=AVERAGE(D2:D3850)
A5: 46047 | B5: 0.24739583 | C5: -7.1600243 | D5: 112.78153 | E5: 60.357825 | H5: Mean Height (m) | I5: =AVERAGE(E2:E3850) -> 58.864984 | J5: '=AVERAGE(E2:E3850)
A6: 46047 | B6: 0.24740741 | C6: -7.1600243 | D6: 112.78153 | E6: 60.364425 | H6: SD Latitude | I6: =SQRT(DEVSQ(C2:C3850)/(COUNT(C2:C3850)-1)) -> 3.6598502e-06 | J6: '=SQRT(DEVSQ(C2:C3850)/(COUNT(C2:C3850)-1))
A7: 46047 | B7: 0.24741898 | C7: -7.1600243 | D7: 112.78153 | E7: 60.363925 | H7: SD Longitude | I7: =SQRT(DEVSQ(D2:D3850)/(COUNT(D2:D3850)-1)) -> 2.4471324e-06 | J7: '=SQRT(DEVSQ(D2:D3850)/(COUNT(D2:D3850)-1))
A8: 46047 | B8: 0.24743056 | C8: -7.1600243 | D8: 112.78153 | E8: 60.364125 | H8: SD Height (m) | I8: =SQRT(DEVSQ(E2:E3850)/(COUNT(E2:E3850)-1)) -> 0.67904702 | J8: '=SQRT(DEVSQ(E2:E3850)/(COUNT(E2:E3850)-1))
A9: 46047 | B9: 0.24744213 | C9: -7.1600243 | D9: 112.78153 | E9: 60.362725 | H9: RMSE Latitude | I9: =SQRT(SUMPRODUCT((C2:C3850-$I$3)*(C2:C3850-$I$3))/COUNT(C2:C3850)) -> 3.6593748e-06 | J9: '=SQRT(SUMPRODUCT((C2:C3850-$I$3)*(C2:C3850-$I$3))/COUNT(C2:C3850))
A10: 46047 | B10: 0.2474537 | C10: -7.1600243 | D10: 112.78153 | E10: 60.363425 | H10: RMSE Longitude | I10: =SQRT(SUMPRODUCT((D2:D3850-$I$4)*(D2:D3850-$I$4))/COUNT(D2:D3850)) -> 2.4468145e-06 | J10: '=SQRT(SUMPRODUCT((D2:D3850-$I$4)*(D2:D3850-$I$4))/COUNT(D2:D3850))
A11: 46047 | B11: 0.24746528 | C11: -7.1600243 | D11: 112.78153 | E11: 60.358325 | H11: RMSE Height (m) | I11: =SQRT(SUMPRODUCT((E2:E3850-$I$5)*(E2:E3850-$I$5))/COUNT(E2:E3850)) -> 0.6789588 | J11: '=SQRT(SUMPRODUCT((E2:E3850-$I$5)*(E2:E3850-$I$5))/COUNT(E2:E3850))
A12: 46047 | B12: 0.24747685 | C12: -7.1600243 | D12: 112.78153 | E12: 60.349525 | H12: Referensi Trimble | I12: BM1 | J12: Referensi BM1
A13: 46047 | B13: 0.24748843 | C13: -7.1600244 | D13: 112.78153 | E13: 60.356325 | H13: Mean Trimble Latitude | I13: -7.1600167 | J13: Nilai mean dari file Trimble BM1
A14: 46047 | B14: 0.2475 | C14: -7.1600244 | D14: 112.78153 | E14: 60.354225 | H14: Mean Trimble Longitude | I14: 112.78153 | J14: Nilai mean dari file Trimble BM1
A15: 46047 | B15: 0.24751157 | C15: -7.1600244 | D15: 112.78153 | E15: 60.349525 | H15: Mean Trimble Height (m) | I15: 58.875071 | J15: Nilai mean dari file Trimble BM1
A16: 46047 | B16: 0.24752315 | C16: -7.1600244 | D16: 112.78153 | E16: 60.347925 | H16: RMSE Latitude vs Trimble | I16: =SQRT(SUMPRODUCT((C2:C3850-$I$13)*(C2:C3850-$I$13))/COUNT(C2:C3850)) -> 3.6600662e-06 | J16: '=SQRT(SUMPRODUCT((C2:C3850-$I$13)*(C2:C3850-$I$13))/COUNT(C2:C3850))
A17: 46047 | B17: 0.24753472 | C17: -7.1600244 | D17: 112.78153 | E17: 60.347725 | H17: RMSE Longitude vs Trimble | I17: =SQRT(SUMPRODUCT((D2:D3850-$I$14)*(D2:D3850-$I$14))/COUNT(D2:D3850)) -> 2.4469003e-06 | J17: '=SQRT(SUMPRODUCT((D2:D3850-$I$14)*(D2:D3850-$I$14))/COUNT(D2:D3850))
A18: 46047 | B18: 0.2475463 | C18: -7.1600243 | D18: 112.78153 | E18: 60.346025 | H18: RMSE Height vs Trimble (m) | I18: =SQRT(SUMPRODUCT((E2:E3850-$I$15)*(E2:E3850-$I$15))/COUNT(E2:E3850)) -> 0.67903373 | J18: '=SQRT(SUMPRODUCT((E2:E3850-$I$15)*(E2:E3850-$I$15))/COUNT(E2:E3850))
A19: 46047 | B19: 0.24755787 | C19: -7.1600244 | D19: 112.78153 | E19: 60.345325
A20: 46047 | B20: 0.24756944 | C20: -7.1600244 | D20: 112.78153 | E20: 60.340425
A21: 46047 | B21: 0.24758102 | C21: -7.1600244 | D21: 112.78153 | E21: 60.344625
A22: 46047 | B22: 0.24759259 | C22: -7.1600244 | D22: 112.78153 | E22: 60.341525
A23: 46047 | B23: 0.24760417 | C23: -7.1600244 | D23: 112.78153 | E23: 60.341025
A24: 46047 | B24: 0.24761574 | C24: -7.1600244 | D24: 112.78153 | E24: 60.341025
A25: 46047 | B25: 0.24762731 | C25: -7.1600244 | D25: 112.78153 | E25: 60.342825
A26: 46047 | B26: 0.24763889 | C26: -7.1600244 | D26: 112.78153 | E26: 60.338425
A27: 46047 | B27: 0.24765046 | C27: -7.1600244 | D27: 112.78153 | E27: 60.339425
A28: 46047 | B28: 0.24766204 | C28: -7.1600244 | D28: 112.78153 | E28: 60.343825
A29: 46047 | B29: 0.24767361 | C29: -7.1600244 | D29: 112.78153 | E29: 60.340525
A30: 46047 | B30: 0.24768519 | C30: -7.1600244 | D30: 112.78153 | E30: 60.341625
... A3850: 46047 | B3850: 0.29189815 | C3850: -7.1600131 | D3850: 112.78153 | E3850: 58.808925

Sheet BM2Day1
A1: Tanggal | B1: Waktu (UTC) | C1: Latitude | D1: Longitude | E1: Height (m) | H1: Statistik | I1: Nilai (Formula Excel) | J1: Formula Teks / Catatan
A2: 46047 | B2: 0.24736111 | C2: -7.1597028 | D2: 112.78236 | E2: 62.301885 | H2: Jumlah Titik | I2: =COUNT(C2:C3919) -> 3918 | J2: '=COUNT(C2:C3919)
A3: 46047 | B3: 0.24737269 | C3: -7.1597028 | D3: 112.78236 | E3: 62.303585 | H3: Mean Latitude | I3: =AVERAGE(C2:C3919) -> -7.1597329 | J3: '=AVERAGE(C2:C3919)
A4: 46047 | B4: 0.24738426 | C4: -7.1597028 | D4: 112.78236 | E4: 62.305485 | H4: Mean Longitude | I4: =AVERAGE(D2:D3919) -> 112.78237 | J4: '=AVERAGE(D2:D3919)
A5: 46047 | B5: 0.24739583 | C5: -7.1597028 | D5: 112.78236 | E5: 62.306385 | H5: Mean Height (m) | I5: =AVERAGE(E2:E3919) -> 57.447582 | J5: '=AVERAGE(E2:E3919)
A6: 46047 | B6: 0.24740741 | C6: -7.1597028 | D6: 112.78236 | E6: 62.306685 | H6: SD Latitude | I6: =SQRT(DEVSQ(C2:C3919)/(COUNT(C2:C3919)-1)) -> 7.5746088e-06 | J6: '=SQRT(DEVSQ(C2:C3919)/(COUNT(C2:C3919)-1))
A7: 46047 | B7: 0.24741898 | C7: -7.1597028 | D7: 112.78236 | E7: 62.305785 | H7: SD Longitude | I7: =SQRT(DEVSQ(D2:D3919)/(COUNT(D2:D3919)-1)) -> 4.0334855e-06 | J7: '=SQRT(DEVSQ(D2:D3919)/(COUNT(D2:D3919)-1))
A8: 46047 | B8: 0.24743056 | C8: -7.1597028 | D8: 112.78236 | E8: 62.306085 | H8: SD Height (m) | I8: =SQRT(DEVSQ(E2:E3919)/(COUNT(E2:E3919)-1)) -> 1.3018437 | J8: '=SQRT(DEVSQ(E2:E3919)/(COUNT(E2:E3919)-1))
A9: 46047 | B9: 0.24744213 | C9: -7.1597028 | D9: 112.78236 | E9: 62.304985 | H9: RMSE Latitude | I9: =SQRT(SUMPRODUCT((C2:C3919-$I$3)*(C2:C3919-$I$3))/COUNT(C2:C3919)) -> 7.5736421e-06 | J9: '=SQRT(SUMPRODUCT((C2:C3919-$I$3)*(C2:C3919-$I$3))/COUNT(C2:C3919))
A10: 46047 | B10: 0.2474537 | C10: -7.1597028 | D10: 112.78236 | E10: 62.306285 | H10: RMSE Longitude | I10: =SQRT(SUMPRODUCT((D2:D3919-$I$4)*(D2:D3919-$I$4))/COUNT(D2:D3919)) -> 4.0329707e-06 | J10: '=SQRT(SUMPRODUCT((D2:D3919-$I$4)*(D2:D3919-$I$4))/COUNT(D2:D3919))
A11: 46047 | B11: 0.24746528 | C11: -7.1597028 | D11: 112.78236 | E11: 62.305985 | H11: RMSE Height (m) | I11: =SQRT(SUMPRODUCT((E2:E3919-$I$5)*(E2:E3919-$I$5))/COUNT(E2:E3919)) -> 1.3016775 | J11: '=SQRT(SUMPRODUCT((E2:E3919-$I$5)*(E2:E3919-$I$5))/COUNT(E2:E3919))
A12: 46047 | B12: 0.24747685 | C12: -7.1597028 | D12: 112.78236 | E12: 62.306585 | H12: Referensi Trimble | I12: BM2 | J12: Referensi BM2
A13: 46047 | B13: 0.24748843 | C13: -7.1597028 | D13: 112.78236 | E13: 62.305185 | H13: Mean Trimble Latitude | I13: -7.1597329 | J13: Nilai mean dari file Trimble BM2
A14: 46047 | B14: 0.2475 | C14: -7.1597028 | D14: 112.78236 | E14: 62.304685 | H14: Mean Trimble Longitude | I14: 112.78237 | J14: Nilai mean dari file Trimble BM2
A15: 46047 | B15: 0.24751157 | C15: -7.1597028 | D15: 112.78236 | E15: 62.305885 | H15: Mean Trimble Height (m) | I15: 57.447582 | J15: Nilai mean dari file Trimble BM2
A16: 46047 | B16: 0.24752315 | C16: -7.1597028 | D16: 112.78236 | E16: 62.303985 | H16: RMSE Latitude vs Trimble | I16: =SQRT(SUMPRODUCT((C2:C3919-$I$13)*(C2:C3919-$I$13))/COUNT(C2:C3919)) -> 7.5736421e-06 | J16: '=SQRT(SUMPRODUCT((C2:C3919-$I$13)*(C2:C3919-$I$13))/COUNT(C2:C3919))
A17: 46047 | B17: 0.24753472 | C17: -7.1597028 | D17: 112.78236 | E17: 62.302985 | H17: RMSE Longitude vs Trimble | I17: =SQRT(SUMPRODUCT((D2:D3919-$I$14)*(D2:D3919-$I$14))/COUNT(D2:D3919)) -> 4.0329707e-06 | J17: '=SQRT(SUMPRODUCT((D2:D3919-$I$14)*(D2:D3919-$I$14))/COUNT(D2:D3919))
A18: 46047 | B18: 0.2475463 | C18: -7.1597028 | D18: 112.78236 | E18: 62.299985 | H18: RMSE Height vs Trimble (m) | I18: =SQRT(SUMPRODUCT((E2:E3919-$I$15)*(E2:E3919-$I$15))/COUNT(E2:E3919)) -> 1.3016775 | J18: '=SQRT(SUMPRODUCT((E2:E3919-$I$15)*(E2:E3919-$I$15))/COUNT(E2:E3919))
A19: 46047 | B19: 0.24755787 | C19: -7.1597028 | D19: 112.78236 | E19: 62.295485
A20: 46047 | B20: 0.24756944 | C20: -7.1597028 | D20: 112.78236 | E20: 62.296385
A21: 46047 | B21: 0.24758102 | C21: -7.1597028 | D21: 112.78236 | E21: 62.293485
A22: 46047 | B22: 0.24759259 | C22: -7.1597028 | D22: 112.78236 | E22: 62.289385
A23: 46047 | B23: 0.24760417 | C23: -7.1597028 | D23: 112.78236 | E23: 62.288885
A24: 46047 | B24: 0.24761574 | C24: -7.1597028 | D24: 112.78236 | E24: 62.286685
A25: 46047 | B25: 0.24762731 | C25: -7.1597028 | D25: 112.78236 | E25: 62.287685
A26: 46047 | B26: 0.24763889 | C26: -7.1597028 | D26: 112.78236 | E26: 62.284085
A27: 46047 | B27: 0.24765046 | C27: -7.1597028 | D27: 112.78236 | E27: 62.280385
A28: 46047 | B28: 0.24766204 | C28: -7.1597028 | D28: 112.78236 | E28: 62.273085
A29: 46047 | B29: 0.24767361 | C29: -7.1597028 | D29: 112.78236 | E29: 62.270885
A30: 46047 | B30: 0.24768519 | C30: -7.1597028 | D30: 112.78236 | E30: 62.269585
... A3919: 46047 | B3919: 0.29269676 | C3919: -7.1597331 | D3919: 112.78236 | E3919: 57.980485

Sheet BM3Day1
A1: Tanggal | B1: Waktu (UTC) | C1: Latitude | D1: Longitude | E1: Height (m) | H1: Statistik | I1: Nilai (Formula Excel) | J1: Formula Teks / Catatan
A2: 46047 | B2: 0.33292824 | C2: -7.1533989 | D2: 112.78357 | E2: 69.593794 | H2: Jumlah Titik | I2: =COUNT(C2:C1136) -> 1135 | J2: '=COUNT(C2:C1136)
A3: 46047 | B3: 0.33293981 | C3: -7.1533989 | D3: 112.78357 | E3: 69.598094 | H3: Mean Latitude | I3: =AVERAGE(C2:C1136) -> -7.153403 | J3: '=AVERAGE(C2:C1136)
A4: 46047 | B4: 0.33295139 | C4: -7.1533989 | D4: 112.78357 | E4: 69.603394 | H4: Mean Longitude | I4: =AVERAGE(D2:D1136) -> 112.78357 | J4: '=AVERAGE(D2:D1136)
A5: 46047 | B5: 0.33296296 | C5: -7.1533989 | D5: 112.78357 | E5: 69.610794 | H5: Mean Height (m) | I5: =AVERAGE(E2:E1136) -> 69.943059 | J5: '=AVERAGE(E2:E1136)
A6: 46047 | B6: 0.33297454 | C6: -7.1533989 | D6: 112.78357 | E6: 69.616394 | H6: SD Latitude | I6: =SQRT(DEVSQ(C2:C1136)/(COUNT(C2:C1136)-1)) -> 2.0636977e-06 | J6: '=SQRT(DEVSQ(C2:C1136)/(COUNT(C2:C1136)-1))
A7: 46047 | B7: 0.33298611 | C7: -7.1533989 | D7: 112.78357 | E7: 69.618194 | H7: SD Longitude | I7: =SQRT(DEVSQ(D2:D1136)/(COUNT(D2:D1136)-1)) -> 1.6967384e-06 | J7: '=SQRT(DEVSQ(D2:D1136)/(COUNT(D2:D1136)-1))
A8: 46047 | B8: 0.33299769 | C8: -7.1533989 | D8: 112.78357 | E8: 69.621794 | H8: SD Height (m) | I8: =SQRT(DEVSQ(E2:E1136)/(COUNT(E2:E1136)-1)) -> 0.12887566 | J8: '=SQRT(DEVSQ(E2:E1136)/(COUNT(E2:E1136)-1))
A9: 46047 | B9: 0.33300926 | C9: -7.1533989 | D9: 112.78357 | E9: 69.626194 | H9: RMSE Latitude | I9: =SQRT(SUMPRODUCT((C2:C1136-$I$3)*(C2:C1136-$I$3))/COUNT(C2:C1136)) -> 2.0627883e-06 | J9: '=SQRT(SUMPRODUCT((C2:C1136-$I$3)*(C2:C1136-$I$3))/COUNT(C2:C1136))
A10: 46047 | B10: 0.33302083 | C10: -7.1533989 | D10: 112.78357 | E10: 69.629294 | H10: RMSE Longitude | I10: =SQRT(SUMPRODUCT((D2:D1136-$I$4)*(D2:D1136-$I$4))/COUNT(D2:D1136)) -> 1.6959908e-06 | J10: '=SQRT(SUMPRODUCT((D2:D1136-$I$4)*(D2:D1136-$I$4))/COUNT(D2:D1136))
A11: 46047 | B11: 0.33303241 | C11: -7.153399 | D11: 112.78357 | E11: 69.633594 | H11: RMSE Height (m) | I11: =SQRT(SUMPRODUCT((E2:E1136-$I$5)*(E2:E1136-$I$5))/COUNT(E2:E1136)) -> 0.12881887 | J11: '=SQRT(SUMPRODUCT((E2:E1136-$I$5)*(E2:E1136-$I$5))/COUNT(E2:E1136))
A12: 46047 | B12: 0.33304398 | C12: -7.153399 | D12: 112.78357 | E12: 69.639594 | H12: Referensi Trimble | I12: BM3 | J12: Referensi BM3
A13: 46047 | B13: 0.33305556 | C13: -7.153399 | D13: 112.78357 | E13: 69.642794 | H13: Mean Trimble Latitude | I13: -7.153403 | J13: Nilai mean dari file Trimble BM3
A14: 46047 | B14: 0.33306713 | C14: -7.153399 | D14: 112.78357 | E14: 69.646994 | H14: Mean Trimble Longitude | I14: 112.78357 | J14: Nilai mean dari file Trimble BM3
A15: 46047 | B15: 0.3330787 | C15: -7.153399 | D15: 112.78357 | E15: 69.653394 | H15: Mean Trimble Height (m) | I15: 69.943059 | J15: Nilai mean dari file Trimble BM3
A16: 46047 | B16: 0.33309028 | C16: -7.153399 | D16: 112.78357 | E16: 69.656594 | H16: RMSE Latitude vs Trimble | I16: =SQRT(SUMPRODUCT((C2:C1136-$I$13)*(C2:C1136-$I$13))/COUNT(C2:C1136)) -> 2.0627883e-06 | J16: '=SQRT(SUMPRODUCT((C2:C1136-$I$13)*(C2:C1136-$I$13))/COUNT(C2:C1136))
A17: 46047 | B17: 0.33310185 | C17: -7.153399 | D17: 112.78357 | E17: 69.661094 | H17: RMSE Longitude vs Trimble | I17: =SQRT(SUMPRODUCT((D2:D1136-$I$14)*(D2:D1136-$I$14))/COUNT(D2:D1136)) -> 1.6959908e-06 | J17: '=SQRT(SUMPRODUCT((D2:D1136-$I$14)*(D2:D1136-$I$14))/COUNT(D2:D1136))
A18: 46047 | B18: 0.33311343 | C18: -7.1533991 | D18: 112.78357 | E18: 69.667494 | H18: RMSE Height vs Trimble (m) | I18: =SQRT(SUMPRODUCT((E2:E1136-$I$15)*(E2:E1136-$I$15))/COUNT(E2:E1136)) -> 0.12881887 | J18: '=SQRT(SUMPRODUCT((E2:E1136-$I$15)*(E2:E1136-$I$15))/COUNT(E2:E1136))
A19: 46047 | B19: 0.333125 | C19: -7.1533991 | D19: 112.78357 | E19: 69.672494
A20: 46047 | B20: 0.33313657 | C20: -7.1533991 | D20: 112.78357 | E20: 69.675894
A21: 46047 | B21: 0.33314815 | C21: -7.1533991 | D21: 112.78357 | E21: 69.680194
A22: 46047 | B22: 0.33315972 | C22: -7.1533991 | D22: 112.78357 | E22: 69.687694
A23: 46047 | B23: 0.3331713 | C23: -7.1533991 | D23: 112.78357 | E23: 69.691594
A24: 46047 | B24: 0.33318287 | C24: -7.1533991 | D24: 112.78357 | E24: 69.697594
A25: 46047 | B25: 0.33319444 | C25: -7.1533991 | D25: 112.78357 | E25: 69.701894
A26: 46047 | B26: 0.33320602 | C26: -7.1533991 | D26: 112.78357 | E26: 69.707094
A27: 46047 | B27: 0.33321759 | C27: -7.1533991 | D27: 112.78357 | E27: 69.711494
A28: 46047 | B28: 0.33322917 | C28: -7.1533992 | D28: 112.78357 | E28: 69.714494
A29: 46047 | B29: 0.33324074 | C29: -7.1533992 | D29: 112.78357 | E29: 69.718894
A30: 46047 | B30: 0.33325231 | C30: -7.1533992 | D30: 112.78357 | E30: 69.724794
... A1136: 46047 | B1136: 0.34605324 | C1136: -7.1534062 | D1136: 112.78357 | E1136: 69.703694

Sheet BM4Day1
A1: Tanggal | B1: Waktu (UTC) | C1: Latitude | D1: Longitude | E1: Height (m) | H1: Statistik | I1: Nilai (Formula Excel) | J1: Formula Teks / Catatan
A2: 46047 | B2: 0.33292824 | C2: -7.1535885 | D2: 112.78383 | E2: 17.951297 | H2: Jumlah Titik | I2: 3753 | J2: '=COUNT(C2:C3715)
A3: 46047 | B3: 0.33293981 | C3: -7.1535885 | D3: 112.78383 | E3: 17.95181 | H3: Mean Latitude | I3: -7.1535853 | J3: '=AVERAGE(C2:C3715)
A4: 46047 | B4: 0.33295139 | C4: -7.1535885 | D4: 112.78383 | E4: 17.945408 | H4: Mean Longitude | I4: 112.78383 | J4: '=AVERAGE(D2:D3715)
A5: 46047 | B5: 0.33296296 | C5: -7.1535885 | D5: 112.78383 | E5: 17.942372 | H5: Mean Height (m) | I5: 17.9377 | J5: '=AVERAGE(E2:E3715)
A6: 46047 | B6: 0.33297454 | C6: -7.1535885 | D6: 112.78383 | E6: 17.940082 | H6: SD Latitude | I6: 1.9098188e-06 | J6: '=SQRT(DEVSQ(C2:C3715)/(COUNT(C2:C3715)-1))
A7: 46047 | B7: 0.33298611 | C7: -7.1535885 | D7: 112.78383 | E7: 17.935072 | H7: SD Longitude | I7: 8.6745256e-07 | J7: '=SQRT(DEVSQ(D2:D3715)/(COUNT(D2:D3715)-1))
A8: 46047 | B8: 0.33299769 | C8: -7.1535884 | D8: 112.78383 | E8: 17.938453 | H8: SD Height (m) | I8: 0.66291309 | J8: '=SQRT(DEVSQ(E2:E3715)/(COUNT(E2:E3715)-1))
A9: 46047 | B9: 0.33300926 | C9: -7.1535884 | D9: 112.78383 | E9: 17.935138 | H9: RMSE Latitude | I9: 1.9095644e-06 | J9: '=SQRT(SUMPRODUCT((C2:C3715-$I$3)*(C2:C3715-$I$3))/COUNT(C2:C3715))
A10: 46047 | B10: 0.33302083 | C10: -7.1535885 | D10: 112.78383 | E10: 17.935326 | H10: RMSE Longitude | I10: 8.6733699e-07 | J10: '=SQRT(SUMPRODUCT((D2:D3715-$I$4)*(D2:D3715-$I$4))/COUNT(D2:D3715))
A11: 46047 | B11: 0.33303241 | C11: -7.1535885 | D11: 112.78383 | E11: 17.936224 | H11: RMSE Height (m) | I11: 0.66282476 | J11: '=SQRT(SUMPRODUCT((E2:E3715-$I$5)*(E2:E3715-$I$5))/COUNT(E2:E3715))
A12: 46047 | B12: 0.33304398 | C12: -7.1535885 | D12: 112.78383 | E12: 17.936078 | H12: Referensi Trimble | I12: BM4 | J12: Referensi BM3 (file Trimble BM4 belum tersedia)
A13: 46047 | B13: 0.33305556 | C13: -7.1535885 | D13: 112.78383 | E13: 17.933717 | H13: Mean Trimble Latitude | I13: -7.1535853 | J13: Nilai mean dari file Trimble BM3
A14: 46047 | B14: 0.33306713 | C14: -7.1535885 | D14: 112.78383 | E14: 17.933507 | H14: Mean Trimble Longitude | I14: 112.78383 | J14: Nilai mean dari file Trimble BM3
A15: 46047 | B15: 0.3330787 | C15: -7.1535885 | D15: 112.78383 | E15: 17.930262 | H15: Mean Trimble Height (m) | I15: 17.9377 | J15: Nilai mean dari file Trimble BM3
A16: 46047 | B16: 0.33309028 | C16: -7.1535884 | D16: 112.78383 | E16: 17.928041 | H16: RMSE Latitude vs Trimble | I16: 1.9095644e-06 | J16: '=SQRT(SUMPRODUCT((C2:C3715-$I$13)*(C2:C3715-$I$13))/COUNT(C2:C3715))
A17: 46047 | B17: 0.33310185 | C17: -7.1535885 | D17: 112.78383 | E17: 17.920339 | H17: RMSE Longitude vs Trimble | I17: 8.6733699e-07 | J17: '=SQRT(SUMPRODUCT((D2:D3715-$I$14)*(D2:D3715-$I$14))/COUNT(D2:D3715))
A18: 46047 | B18: 0.33311343 | C18: -7.1535884 | D18: 112.78383 | E18: 17.919849 | H18: RMSE Height vs Trimble (m) | I18: 0.66282476 | J18: '=SQRT(SUMPRODUCT((E2:E3715-$I$15)*(E2:E3715-$I$15))/COUNT(E2:E3715))
A19: 46047 | B19: 0.333125 | C19: -7.1535884 | D19: 112.78383 | E19: 17.917626
A20: 46047 | B20: 0.33313657 | C20: -7.1535884 | D20: 112.78383 | E20: 17.922436
A21: 46047 | B21: 0.33314815 | C21: -7.1535884 | D21: 112.78383 | E21: 17.921958
A22: 46047 | B22: 0.33315972 | C22: -7.1535884 | D22: 112.78383 | E22: 17.920457
A23: 46047 | B23: 0.3331713 | C23: -7.1535885 | D23: 112.78383 | E23: 17.916997
A24: 46047 | B24: 0.33318287 | C24: -7.1535885 | D24: 112.78383 | E24: 17.9157
A25: 46047 | B25: 0.33319444 | C25: -7.1535885 | D25: 112.78383 | E25: 17.912667
A26: 46047 | B26: 0.33320602 | C26: -7.1535884 | D26: 112.78383 | E26: 17.917729
A27: 46047 | B27: 0.33321759 | C27: -7.1535884 | D27: 112.78383 | E27: 17.918998
A28: 46047 | B28: 0.33322917 | C28: -7.1535884 | D28: 112.78383 | E28: 17.910933
A29: 46047 | B29: 0.33324074 | C29: -7.1535884 | D29: 112.78383 | E29: 17.910814
A30: 46047 | B30: 0.33325231 | C30: -7.1535885 | D30: 112.78383 | E30: 17.90435
... A3754: 46047 | B3754: 0.37635417 | C3754: -7.1535804 | D3754: 112.78383 | E3754: 18.848515

Sheet BM1Day2
A1: Tanggal | B1: Waktu (UTC) | C1: Latitude | D1: Longitude | E1: Height (m) | H1: Statistik | I1: Nilai (Formula Excel) | J1: Formula Teks / Catatan
A2: 46053 | B2: 0.13834491 | C2: -7.1600169 | D2: 112.78153 | E2: 58.981288 | H2: Jumlah Titik | I2: =COUNT(C2:C1502) -> 1501 | J2: '=COUNT(C2:C1502)
A3: 46053 | B3: 0.13835648 | C3: -7.1600169 | D3: 112.78153 | E3: 58.978622 | H3: Mean Latitude | I3: =AVERAGE(C2:C1502) -> -7.1600167 | J3: '=AVERAGE(C2:C1502)
A4: 46053 | B4: 0.13836806 | C4: -7.1600169 | D4: 112.78153 | E4: 58.973955 | H4: Mean Longitude | I4: =AVERAGE(D2:D1502) -> 112.78153 | J4: '=AVERAGE(D2:D1502)
A5: 46053 | B5: 0.13837963 | C5: -7.1600168 | D5: 112.78153 | E5: 58.970545 | H5: Mean Height (m) | I5: =AVERAGE(E2:E1502) -> 58.875071 | J5: '=AVERAGE(E2:E1502)
A6: 46053 | B6: 0.1383912 | C6: -7.1600168 | D6: 112.78153 | E6: 58.967123 | H6: SD Latitude | I6: =SQRT(DEVSQ(C2:C1502)/(COUNT(C2:C1502)-1)) -> 6.6684755e-07 | J6: '=SQRT(DEVSQ(C2:C1502)/(COUNT(C2:C1502)-1))
A7: 46053 | B7: 0.13840278 | C7: -7.1600168 | D7: 112.78153 | E7: 58.96592 | H7: SD Longitude | I7: =SQRT(DEVSQ(D2:D1502)/(COUNT(D2:D1502)-1)) -> 3.5003151e-07 | J7: '=SQRT(DEVSQ(D2:D1502)/(COUNT(D2:D1502)-1))
A8: 46053 | B8: 0.13841435 | C8: -7.1600168 | D8: 112.78153 | E8: 58.965964 | H8: SD Height (m) | I8: =SQRT(DEVSQ(E2:E1502)/(COUNT(E2:E1502)-1)) -> 0.066461923 | J8: '=SQRT(DEVSQ(E2:E1502)/(COUNT(E2:E1502)-1))
A9: 46053 | B9: 0.13842593 | C9: -7.1600168 | D9: 112.78153 | E9: 58.966644 | H9: RMSE Latitude | I9: =SQRT(SUMPRODUCT((C2:C1502-$I$3)*(C2:C1502-$I$3))/COUNT(C2:C1502)) -> 6.6662538e-07 | J9: '=SQRT(SUMPRODUCT((C2:C1502-$I$3)*(C2:C1502-$I$3))/COUNT(C2:C1502))
A10: 46053 | B10: 0.1384375 | C10: -7.1600168 | D10: 112.78153 | E10: 58.968408 | H10: RMSE Longitude | I10: =SQRT(SUMPRODUCT((D2:D1502-$I$4)*(D2:D1502-$I$4))/COUNT(D2:D1502)) -> 3.4991489e-07 | J10: '=SQRT(SUMPRODUCT((D2:D1502-$I$4)*(D2:D1502-$I$4))/COUNT(D2:D1502))
A11: 46053 | B11: 0.13844907 | C11: -7.1600168 | D11: 112.78153 | E11: 58.969729 | H11: RMSE Height (m) | I11: =SQRT(SUMPRODUCT((E2:E1502-$I$5)*(E2:E1502-$I$5))/COUNT(E2:E1502)) -> 0.06643978 | J11: '=SQRT(SUMPRODUCT((E2:E1502-$I$5)*(E2:E1502-$I$5))/COUNT(E2:E1502))
A12: 46053 | B12: 0.13846065 | C12: -7.1600168 | D12: 112.78153 | E12: 58.968967 | H12: Referensi Trimble | I12: BM1 | J12: Referensi BM1
A13: 46053 | B13: 0.13847222 | C13: -7.1600168 | D13: 112.78153 | E13: 58.964125 | H13: Mean Trimble Latitude | I13: -7.1600167 | J13: Nilai mean dari file Trimble BM1
A14: 46053 | B14: 0.1384838 | C14: -7.1600168 | D14: 112.78153 | E14: 58.962436 | H14: Mean Trimble Longitude | I14: 112.78153 | J14: Nilai mean dari file Trimble BM1
A15: 46053 | B15: 0.13849537 | C15: -7.1600168 | D15: 112.78153 | E15: 58.961404 | H15: Mean Trimble Height (m) | I15: 58.875071 | J15: Nilai mean dari file Trimble BM1
A16: 46053 | B16: 0.13850694 | C16: -7.1600168 | D16: 112.78153 | E16: 58.960053 | H16: RMSE Latitude vs Trimble | I16: =SQRT(SUMPRODUCT((C2:C1502-$I$13)*(C2:C1502-$I$13))/COUNT(C2:C1502)) -> 6.6662538e-07 | J16: '=SQRT(SUMPRODUCT((C2:C1502-$I$13)*(C2:C1502-$I$13))/COUNT(C2:C1502))
A17: 46053 | B17: 0.13851852 | C17: -7.1600167 | D17: 112.78153 | E17: 58.959638 | H17: RMSE Longitude vs Trimble | I17: =SQRT(SUMPRODUCT((D2:D1502-$I$14)*(D2:D1502-$I$14))/COUNT(D2:D1502)) -> 3.4991489e-07 | J17: '=SQRT(SUMPRODUCT((D2:D1502-$I$14)*(D2:D1502-$I$14))/COUNT(D2:D1502))
A18: 46053 | B18: 0.13853009 | C18: -7.1600167 | D18: 112.78153 | E18: 58.959924 | H18: RMSE Height vs Trimble (m) | I18: =SQRT(SUMPRODUCT((E2:E1502-$I$15)*(E2:E1502-$I$15))/COUNT(E2:E1502)) -> 0.06643978 | J18: '=SQRT(SUMPRODUCT((E2:E1502-$I$15)*(E2:E1502-$I$15))/COUNT(E2:E1502))
A19: 46053 | B19: 0.13854167 | C19: -7.1600168 | D19: 112.78153 | E19: 58.961056
A20: 46053 | B20: 0.13855324 | C20: -7.1600167 | D20: 112.78153 | E20: 58.961582
A21: 46053 | B21: 0.13856481 | C21: -7.1600167 | D21: 112.78153 | E21: 58.962945
A22: 46053 | B22: 0.13857639 | C22: -7.1600167 | D22: 112.78153 | E22: 58.962122
A23: 46053 | B23: 0.13858796 | C23: -7.1600167 | D23: 112.78153 | E23: 58.963152
A24: 46053 | B24: 0.13859954 | C24: -7.1600167 | D24: 112.78153 | E24: 58.965821
A25: 46053 | B25: 0.13861111 | C25: -7.1600168 | D25: 112.78153 | E25: 58.966683
A26: 46053 | B26: 0.13862269 | C26: -7.1600168 | D26: 112.78153 | E26: 58.965939
A27: 46053 | B27: 0.13863426 | C27: -7.1600168 | D27: 112.78153 | E27: 58.96656
A28: 46053 | B28: 0.13864583 | C28: -7.1600168 | D28: 112.78153 | E28: 58.967937
A29: 46053 | B29: 0.13865741 | C29: -7.1600168 | D29: 112.78153 | E29: 58.967056
A30: 46053 | B30: 0.13866898 | C30: -7.1600167 | D30: 112.78153 | E30: 58.964648
... A1502: 46053 | B1502: 0.15570602 | C1502: -7.1600161 | D1502: 112.78153 | E1502: 58.897392

Sheet BM2Day2
A1: Tanggal | B1: Waktu (UTC) | C1: Latitude | D1: Longitude | E1: Height (m) | H1: Statistik | I1: Nilai (Formula Excel) | J1: Formula Teks / Catatan
A2: 46053 | B2: 0.1221412 | C2: -7.1597307 | D2: 112.78237 | E2: 57.585721 | H2: Jumlah Titik | I2: =COUNT(C2:C1086) -> 1085 | J2: '=COUNT(C2:C1086)
A3: 46053 | B3: 0.12215278 | C3: -7.1597307 | D3: 112.78237 | E3: 57.58551 | H3: Mean Latitude | I3: =AVERAGE(C2:C1086) -> -7.1597329 | J3: '=AVERAGE(C2:C1086)
A4: 46053 | B4: 0.12216435 | C4: -7.1597307 | D4: 112.78237 | E4: 57.584407 | H4: Mean Longitude | I4: =AVERAGE(D2:D1086) -> 112.78237 | J4: '=AVERAGE(D2:D1086)
A5: 46053 | B5: 0.12217593 | C5: -7.1597307 | D5: 112.78237 | E5: 57.583067 | H5: Mean Height (m) | I5: =AVERAGE(E2:E1086) -> 57.447582 | J5: '=AVERAGE(E2:E1086)
A6: 46053 | B6: 0.1221875 | C6: -7.1597306 | D6: 112.78237 | E6: 57.58014 | H6: SD Latitude | I6: =SQRT(DEVSQ(C2:C1086)/(COUNT(C2:C1086)-1)) -> 1.8432765e-06 | J6: '=SQRT(DEVSQ(C2:C1086)/(COUNT(C2:C1086)-1))
A7: 46053 | B7: 0.12219907 | C7: -7.1597306 | D7: 112.78237 | E7: 57.580723 | H7: SD Longitude | I7: =SQRT(DEVSQ(D2:D1086)/(COUNT(D2:D1086)-1)) -> 1.0932501e-06 | J7: '=SQRT(DEVSQ(D2:D1086)/(COUNT(D2:D1086)-1))
A8: 46053 | B8: 0.12221065 | C8: -7.1597306 | D8: 112.78237 | E8: 57.579544 | H8: SD Height (m) | I8: =SQRT(DEVSQ(E2:E1086)/(COUNT(E2:E1086)-1)) -> 0.15509242 | J8: '=SQRT(DEVSQ(E2:E1086)/(COUNT(E2:E1086)-1))
A9: 46053 | B9: 0.12222222 | C9: -7.1597306 | D9: 112.78237 | E9: 57.57853 | H9: RMSE Latitude | I9: =SQRT(SUMPRODUCT((C2:C1086-$I$3)*(C2:C1086-$I$3))/COUNT(C2:C1086)) -> 1.8424269e-06 | J9: '=SQRT(SUMPRODUCT((C2:C1086-$I$3)*(C2:C1086-$I$3))/COUNT(C2:C1086))
A10: 46053 | B10: 0.1222338 | C10: -7.1597305 | D10: 112.78237 | E10: 57.576882 | H10: RMSE Longitude | I10: =SQRT(SUMPRODUCT((D2:D1086-$I$4)*(D2:D1086-$I$4))/COUNT(D2:D1086)) -> 1.0927462e-06 | J10: '=SQRT(SUMPRODUCT((D2:D1086-$I$4)*(D2:D1086-$I$4))/COUNT(D2:D1086))
A11: 46053 | B11: 0.12224537 | C11: -7.1597305 | D11: 112.78237 | E11: 57.577465 | H11: RMSE Height (m) | I11: =SQRT(SUMPRODUCT((E2:E1086-$I$5)*(E2:E1086-$I$5))/COUNT(E2:E1086)) -> 0.15502094 | J11: '=SQRT(SUMPRODUCT((E2:E1086-$I$5)*(E2:E1086-$I$5))/COUNT(E2:E1086))
A12: 46053 | B12: 0.12225694 | C12: -7.1597305 | D12: 112.78237 | E12: 57.576981 | H12: Referensi Trimble | I12: BM2 | J12: Referensi BM2
A13: 46053 | B13: 0.12226852 | C13: -7.1597305 | D13: 112.78237 | E13: 57.575462 | H13: Mean Trimble Latitude | I13: -7.1597329 | J13: Nilai mean dari file Trimble BM2
A14: 46053 | B14: 0.12228009 | C14: -7.1597306 | D14: 112.78237 | E14: 57.578389 | H14: Mean Trimble Longitude | I14: 112.78237 | J14: Nilai mean dari file Trimble BM2
A15: 46053 | B15: 0.12229167 | C15: -7.1597306 | D15: 112.78237 | E15: 57.580039 | H15: Mean Trimble Height (m) | I15: 57.447582 | J15: Nilai mean dari file Trimble BM2
A16: 46053 | B16: 0.12230324 | C16: -7.1597307 | D16: 112.78237 | E16: 57.581723 | H16: RMSE Latitude vs Trimble | I16: =SQRT(SUMPRODUCT((C2:C1086-$I$13)*(C2:C1086-$I$13))/COUNT(C2:C1086)) -> 1.8424269e-06 | J16: '=SQRT(SUMPRODUCT((C2:C1086-$I$13)*(C2:C1086-$I$13))/COUNT(C2:C1086))
A17: 46053 | B17: 0.12231481 | C17: -7.1597307 | D17: 112.78237 | E17: 57.583186 | H17: RMSE Longitude vs Trimble | I17: =SQRT(SUMPRODUCT((D2:D1086-$I$14)*(D2:D1086-$I$14))/COUNT(D2:D1086)) -> 1.0927462e-06 | J17: '=SQRT(SUMPRODUCT((D2:D1086-$I$14)*(D2:D1086-$I$14))/COUNT(D2:D1086))
A18: 46053 | B18: 0.12232639 | C18: -7.1597308 | D18: 112.78237 | E18: 57.58467 | H18: RMSE Height vs Trimble (m) | I18: =SQRT(SUMPRODUCT((E2:E1086-$I$15)*(E2:E1086-$I$15))/COUNT(E2:E1086)) -> 0.15502094 | J18: '=SQRT(SUMPRODUCT((E2:E1086-$I$15)*(E2:E1086-$I$15))/COUNT(E2:E1086))
A19: 46053 | B19: 0.12233796 | C19: -7.1597308 | D19: 112.78237 | E19: 57.58435
A20: 46053 | B20: 0.12234954 | C20: -7.1597309 | D20: 112.78237 | E20: 57.58724
A21: 46053 | B21: 0.12236111 | C21: -7.1597309 | D21: 112.78237 | E21: 57.588498
A22: 46053 | B22: 0.12237269 | C22: -7.1597309 | D22: 112.78237 | E22: 57.580343
A23: 46053 | B23: 0.12238426 | C23: -7.1597309 | D23: 112.78237 | E23: 57.582312
A24: 46053 | B24: 0.12239583 | C24: -7.1597309 | D24: 112.78237 | E24: 57.582339
A25: 46053 | B25: 0.12240741 | C25: -7.159731 | D25: 112.78237 | E25: 57.582399
A26: 46053 | B26: 0.12241898 | C26: -7.159731 | D26: 112.78237 | E26: 57.58171
A27: 46053 | B27: 0.12243056 | C27: -7.159731 | D27: 112.78237 | E27: 57.580875
A28: 46053 | B28: 0.12244213 | C28: -7.159731 | D28: 112.78237 | E28: 57.58065
A29: 46053 | B29: 0.1224537 | C29: -7.159731 | D29: 112.78237 | E29: 57.581826
A30: 46053 | B30: 0.12246528 | C30: -7.159731 | D30: 112.78237 | E30: 57.579845
... A1086: 46053 | B1086: 0.13475694 | C1086: -7.1597341 | D1086: 112.78237 | E1086: 57.384395

Sheet BM3Day2
A1: Tanggal | B1: Waktu (UTC) | C1: Latitude | D1: Longitude | E1: Height (m) | H1: Statistik | I1: Nilai (Formula Excel) | J1: Formula Teks / Catatan
A2: 46053 | B2: 0.20212963 | C2: -7.1534043 | D2: 112.78357 | E2: 70.067135 | H2: Jumlah Titik | I2: =COUNT(C2:C3957) -> 3956 | J2: '=COUNT(C2:C3957)
A3: 46053 | B3: 0.2021412 | C3: -7.1534043 | D3: 112.78357 | E3: 70.070488 | H3: Mean Latitude | I3: =AVERAGE(C2:C3957) -> -7.153403 | J3: '=AVERAGE(C2:C3957)
A4: 46053 | B4: 0.20215278 | C4: -7.1534043 | D4: 112.78357 | E4: 70.069723 | H4: Mean Longitude | I4: =AVERAGE(D2:D3957) -> 112.78357 | J4: '=AVERAGE(D2:D3957)
A5: 46053 | B5: 0.20216435 | C5: -7.1534043 | D5: 112.78357 | E5: 70.06969 | H5: Mean Height (m) | I5: =AVERAGE(E2:E3957) -> 69.943059 | J5: '=AVERAGE(E2:E3957)
A6: 46053 | B6: 0.20217593 | C6: -7.1534043 | D6: 112.78357 | E6: 70.070832 | H6: SD Latitude | I6: =SQRT(DEVSQ(C2:C3957)/(COUNT(C2:C3957)-1)) -> 2.1452748e-06 | J6: '=SQRT(DEVSQ(C2:C3957)/(COUNT(C2:C3957)-1))
A7: 46053 | B7: 0.2021875 | C7: -7.1534043 | D7: 112.78357 | E7: 70.070649 | H7: SD Longitude | I7: =SQRT(DEVSQ(D2:D3957)/(COUNT(D2:D3957)-1)) -> 8.5831586e-07 | J7: '=SQRT(DEVSQ(D2:D3957)/(COUNT(D2:D3957)-1))
A8: 46053 | B8: 0.20219907 | C8: -7.1534043 | D8: 112.78357 | E8: 70.069228 | H8: SD Height (m) | I8: =SQRT(DEVSQ(E2:E3957)/(COUNT(E2:E3957)-1)) -> 0.14534571 | J8: '=SQRT(DEVSQ(E2:E3957)/(COUNT(E2:E3957)-1))
A9: 46053 | B9: 0.20221065 | C9: -7.1534043 | D9: 112.78357 | E9: 70.068312 | H9: RMSE Latitude | I9: =SQRT(SUMPRODUCT((C2:C3957-$I$3)*(C2:C3957-$I$3))/COUNT(C2:C3957)) -> 2.1450036e-06 | J9: '=SQRT(SUMPRODUCT((C2:C3957-$I$3)*(C2:C3957-$I$3))/COUNT(C2:C3957))
A10: 46053 | B10: 0.20222222 | C10: -7.1534043 | D10: 112.78357 | E10: 70.068176 | H10: RMSE Longitude | I10: =SQRT(SUMPRODUCT((D2:D3957-$I$4)*(D2:D3957-$I$4))/COUNT(D2:D3957)) -> 8.5820737e-07 | J10: '=SQRT(SUMPRODUCT((D2:D3957-$I$4)*(D2:D3957-$I$4))/COUNT(D2:D3957))
A11: 46053 | B11: 0.2022338 | C11: -7.1534043 | D11: 112.78357 | E11: 70.067849 | H11: RMSE Height (m) | I11: =SQRT(SUMPRODUCT((E2:E3957-$I$5)*(E2:E3957-$I$5))/COUNT(E2:E3957)) -> 0.14532734 | J11: '=SQRT(SUMPRODUCT((E2:E3957-$I$5)*(E2:E3957-$I$5))/COUNT(E2:E3957))
A12: 46053 | B12: 0.20224537 | C12: -7.1534043 | D12: 112.78357 | E12: 70.067546 | H12: Referensi Trimble | I12: BM3 | J12: Referensi BM3
A13: 46053 | B13: 0.20225694 | C13: -7.1534043 | D13: 112.78357 | E13: 70.066401 | H13: Mean Trimble Latitude | I13: -7.153403 | J13: Nilai mean dari file Trimble BM3
A14: 46053 | B14: 0.20226852 | C14: -7.1534043 | D14: 112.78357 | E14: 70.064988 | H14: Mean Trimble Longitude | I14: 112.78357 | J14: Nilai mean dari file Trimble BM3
A15: 46053 | B15: 0.20228009 | C15: -7.1534043 | D15: 112.78357 | E15: 70.064453 | H15: Mean Trimble Height (m) | I15: 69.943059 | J15: Nilai mean dari file Trimble BM3
A16: 46053 | B16: 0.20229167 | C16: -7.1534043 | D16: 112.78357 | E16: 70.065246 | H16: RMSE Latitude vs Trimble | I16: =SQRT(SUMPRODUCT((C2:C3957-$I$13)*(C2:C3957-$I$13))/COUNT(C2:C3957)) -> 2.1450036e-06 | J16: '=SQRT(SUMPRODUCT((C2:C3957-$I$13)*(C2:C3957-$I$13))/COUNT(C2:C3957))
A17: 46053 | B17: 0.20230324 | C17: -7.1534043 | D17: 112.78357 | E17: 70.063077 | H17: RMSE Longitude vs Trimble | I17: =SQRT(SUMPRODUCT((D2:D3957-$I$14)*(D2:D3957-$I$14))/COUNT(D2:D3957)) -> 8.5820737e-07 | J17: '=SQRT(SUMPRODUCT((D2:D3957-$I$14)*(D2:D3957-$I$14))/COUNT(D2:D3957))
A18: 46053 | B18: 0.20231481 | C18: -7.1534043 | D18: 112.78357 | E18: 70.060664 | H18: RMSE Height vs Trimble (m) | I18: =SQRT(SUMPRODUCT((E2:E3957-$I$15)*(E2:E3957-$I$15))/COUNT(E2:E3957)) -> 0.14532734 | J18: '=SQRT(SUMPRODUCT((E2:E3957-$I$15)*(E2:E3957-$I$15))/COUNT(E2:E3957))
A19: 46053 | B19: 0.20232639 | C19: -7.1534043 | D19: 112.78357 | E19: 70.057045
A20: 46053 | B20: 0.20233796 | C20: -7.1534043 | D20: 112.78357 | E20: 70.054356
A21: 46053 | B21: 0.20234954 | C21: -7.1534043 | D21: 112.78357 | E21: 70.054334
A22: 46053 | B22: 0.20236111 | C22: -7.1534043 | D22: 112.78357 | E22: 70.056331
A23: 46053 | B23: 0.20237269 | C23: -7.1534044 | D23: 112.78357 | E23: 70.057885
A24: 46053 | B24: 0.20238426 | C24: -7.1534044 | D24: 112.78357 | E24: 70.060517
A25: 46053 | B25: 0.20239583 | C25: -7.1534044 | D25: 112.78357 | E25: 70.0608
A26: 46053 | B26: 0.20240741 | C26: -7.1534044 | D26: 112.78357 | E26: 70.06239
A27: 46053 | B27: 0.20241898 | C27: -7.1534044 | D27: 112.78357 | E27: 70.063392
A28: 46053 | B28: 0.20243056 | C28: -7.1534044 | D28: 112.78357 | E28: 70.064443
A29: 46053 | B29: 0.20244213 | C29: -7.1534044 | D29: 112.78357 | E29: 70.067005
A30: 46053 | B30: 0.2024537 | C30: -7.1534044 | D30: 112.78357 | E30: 70.067742
... A3957: 46053 | B3957: 0.24790509 | C3957: -7.153403 | D3957: 112.78357 | E3957: 70.044325

Sheet BM4Day2
A1: Tanggal | B1: Waktu (UTC) | C1: Latitude | D1: Longitude | E1: Height (m) | H1: Statistik | I1: Nilai (Formula Excel) | J1: Formula Teks / Catatan
A2: 46056 | B2: 0.18513889 | C2: -7.1535574 | D2: 112.78383 | E2: 19.404753 | H2: Jumlah Titik | I2: 3714 | J2: '=COUNT(C2:C3754)
A3: 46056 | B3: 0.18515046 | C3: -7.1535575 | D3: 112.78383 | E3: 19.400655 | H3: Mean Latitude | I3: -7.1535853 | J3: '=AVERAGE(C2:C3754)
A4: 46056 | B4: 0.18516204 | C4: -7.1535576 | D4: 112.78383 | E4: 19.396622 | H4: Mean Longitude | I4: 112.78383 | J4: '=AVERAGE(D2:D3754)
A5: 46056 | B5: 0.18517361 | C5: -7.1535577 | D5: 112.78383 | E5: 19.393374 | H5: Mean Height (m) | I5: 17.9377 | J5: '=AVERAGE(E2:E3754)
A6: 46056 | B6: 0.18518519 | C6: -7.1535579 | D6: 112.78383 | E6: 19.389788 | H6: SD Latitude | I6: 6.2875883e-06 | J6: '=SQRT(DEVSQ(C2:C3754)/(COUNT(C2:C3754)-1))
A7: 46056 | B7: 0.18519676 | C7: -7.153558 | D7: 112.78383 | E7: 19.38735 | H7: SD Longitude | I7: 6.4208352e-06 | J7: '=SQRT(DEVSQ(D2:D3754)/(COUNT(D2:D3754)-1))
A8: 46056 | B8: 0.18520833 | C8: -7.1535581 | D8: 112.78383 | E8: 19.390068 | H8: SD Height (m) | I8: 0.71776148 | J8: '=SQRT(DEVSQ(E2:E3754)/(COUNT(E2:E3754)-1))
A9: 46056 | B9: 0.18521991 | C9: -7.1535582 | D9: 112.78383 | E9: 19.388546 | H9: RMSE Latitude | I9: 6.2867418e-06 | J9: '=SQRT(SUMPRODUCT((C2:C3754-$I$3)*(C2:C3754-$I$3))/COUNT(C2:C3754))
A10: 46056 | B10: 0.18523148 | C10: -7.1535583 | D10: 112.78383 | E10: 19.387881 | H10: RMSE Longitude | I10: 6.4199707e-06 | J10: '=SQRT(SUMPRODUCT((D2:D3754-$I$4)*(D2:D3754-$I$4))/COUNT(D2:D3754))
A11: 46056 | B11: 0.18524306 | C11: -7.1535584 | D11: 112.78383 | E11: 19.385508 | H11: RMSE Height (m) | I11: 0.71766484 | J11: '=SQRT(SUMPRODUCT((E2:E3754-$I$5)*(E2:E3754-$I$5))/COUNT(E2:E3754))
A12: 46056 | B12: 0.18525463 | C12: -7.1535585 | D12: 112.78383 | E12: 19.381035 | H12: Referensi Trimble | I12: BM4 | J12: Referensi BM3 (file Trimble BM4 belum tersedia)
A13: 46056 | B13: 0.1852662 | C13: -7.1535587 | D13: 112.78383 | E13: 19.379178 | H13: Mean Trimble Latitude | I13: -7.1535853 | J13: Nilai mean dari file Trimble BM3
A14: 46056 | B14: 0.18527778 | C14: -7.1535588 | D14: 112.78383 | E14: 19.376225 | H14: Mean Trimble Longitude | I14: 112.78383 | J14: Nilai mean dari file Trimble BM3
A15: 46056 | B15: 0.18528935 | C15: -7.1535589 | D15: 112.78383 | E15: 19.374108 | H15: Mean Trimble Height (m) | I15: 17.9377 | J15: Nilai mean dari file Trimble BM3
A16: 46056 | B16: 0.18530093 | C16: -7.153559 | D16: 112.78383 | E16: 19.373054 | H16: RMSE Latitude vs Trimble | I16: 6.2867418e-06 | J16: '=SQRT(SUMPRODUCT((C2:C3754-$I$13)*(C2:C3754-$I$13))/COUNT(C2:C3754))
A17: 46056 | B17: 0.1853125 | C17: -7.1535591 | D17: 112.78383 | E17: 19.36884 | H17: RMSE Longitude vs Trimble | I17: 6.4199707e-06 | J17: '=SQRT(SUMPRODUCT((D2:D3754-$I$14)*(D2:D3754-$I$14))/COUNT(D2:D3754))
A18: 46056 | B18: 0.18532407 | C18: -7.1535591 | D18: 112.78383 | E18: 19.365467 | H18: RMSE Height vs Trimble (m) | I18: 0.71766484 | J18: '=SQRT(SUMPRODUCT((E2:E3754-$I$15)*(E2:E3754-$I$15))/COUNT(E2:E3754))
A19: 46056 | B19: 0.18533565 | C19: -7.1535592 | D19: 112.78383 | E19: 19.363817
A20: 46056 | B20: 0.18534722 | C20: -7.1535593 | D20: 112.78383 | E20: 19.362325
A21: 46056 | B21: 0.1853588 | C21: -7.1535594 | D21: 112.78383 | E21: 19.35737
A22: 46056 | B22: 0.18537037 | C22: -7.1535595 | D22: 112.78383 | E22: 19.353128
A23: 46056 | B23: 0.18538194 | C23: -7.1535596 | D23: 112.78383 | E23: 19.349175
A24: 46056 | B24: 0.18539352 | C24: -7.1535597 | D24: 112.78383 | E24: 19.346343
A25: 46056 | B25: 0.18540509 | C25: -7.1535598 | D25: 112.78383 | E25: 19.345659
A26: 46056 | B26: 0.18541667 | C26: -7.1535599 | D26: 112.78383 | E26: 19.343259
A27: 46056 | B27: 0.18542824 | C27: -7.1535601 | D27: 112.78383 | E27: 19.338639
A28: 46056 | B28: 0.18543981 | C28: -7.1535602 | D28: 112.78383 | E28: 19.334299
A29: 46056 | B29: 0.18545139 | C29: -7.1535603 | D29: 112.78383 | E29: 19.329174
A30: 46056 | B30: 0.18546296 | C30: -7.1535604 | D30: 112.78383 | E30: 19.325638
... A3715: 46056 | B3715: 0.22811343 | C3715: -7.1535895 | D3715: 112.78384 | E3715: 18.243613

Sheet BM1Day3
A1: Tanggal | B1: Waktu (UTC) | C1: Latitude | D1: Longitude | E1: Height (m) | H1: Statistik | I1: Nilai (Formula Excel) | J1: Formula Teks / Catatan
A2: 46056 | B2: 0.12322917 | C2: -7.1600157 | D2: 112.78153 | E2: 58.40571 | H2: Jumlah Titik | I2: =COUNT(C2:C2369) -> 2368 | J2: '=COUNT(C2:C2369)
A3: 46056 | B3: 0.12324074 | C3: -7.1600157 | D3: 112.78153 | E3: 58.409331 | H3: Mean Latitude | I3: =AVERAGE(C2:C2369) -> -7.1600167 | J3: '=AVERAGE(C2:C2369)
A4: 46056 | B4: 0.12325231 | C4: -7.1600158 | D4: 112.78153 | E4: 58.410874 | H4: Mean Longitude | I4: =AVERAGE(D2:D2369) -> 112.78153 | J4: '=AVERAGE(D2:D2369)
A5: 46056 | B5: 0.12326389 | C5: -7.1600158 | D5: 112.78153 | E5: 58.411823 | H5: Mean Height (m) | I5: =AVERAGE(E2:E2369) -> 58.875071 | J5: '=AVERAGE(E2:E2369)
A6: 46056 | B6: 0.12327546 | C6: -7.1600158 | D6: 112.78153 | E6: 58.410268 | H6: SD Latitude | I6: =SQRT(DEVSQ(C2:C2369)/(COUNT(C2:C2369)-1)) -> 6.8054075e-07 | J6: '=SQRT(DEVSQ(C2:C2369)/(COUNT(C2:C2369)-1))
A7: 46056 | B7: 0.12328704 | C7: -7.1600158 | D7: 112.78153 | E7: 58.409669 | H7: SD Longitude | I7: =SQRT(DEVSQ(D2:D2369)/(COUNT(D2:D2369)-1)) -> 1.1768247e-06 | J7: '=SQRT(DEVSQ(D2:D2369)/(COUNT(D2:D2369)-1))
A8: 46056 | B8: 0.12329861 | C8: -7.1600158 | D8: 112.78153 | E8: 58.409255 | H8: SD Height (m) | I8: =SQRT(DEVSQ(E2:E2369)/(COUNT(E2:E2369)-1)) -> 0.37846817 | J8: '=SQRT(DEVSQ(E2:E2369)/(COUNT(E2:E2369)-1))
A9: 46056 | B9: 0.12331019 | C9: -7.1600158 | D9: 112.78153 | E9: 58.410441 | H9: RMSE Latitude | I9: =SQRT(SUMPRODUCT((C2:C2369-$I$3)*(C2:C2369-$I$3))/COUNT(C2:C2369)) -> 6.8039704e-07 | J9: '=SQRT(SUMPRODUCT((C2:C2369-$I$3)*(C2:C2369-$I$3))/COUNT(C2:C2369))
A10: 46056 | B10: 0.12332176 | C10: -7.1600158 | D10: 112.78153 | E10: 58.412677 | H10: RMSE Longitude | I10: =SQRT(SUMPRODUCT((D2:D2369-$I$4)*(D2:D2369-$I$4))/COUNT(D2:D2369)) -> 1.1765762e-06 | J10: '=SQRT(SUMPRODUCT((D2:D2369-$I$4)*(D2:D2369-$I$4))/COUNT(D2:D2369))
A11: 46056 | B11: 0.12333333 | C11: -7.1600158 | D11: 112.78153 | E11: 58.410922 | H11: RMSE Height (m) | I11: =SQRT(SUMPRODUCT((E2:E2369-$I$5)*(E2:E2369-$I$5))/COUNT(E2:E2369)) -> 0.37838825 | J11: '=SQRT(SUMPRODUCT((E2:E2369-$I$5)*(E2:E2369-$I$5))/COUNT(E2:E2369))
A12: 46056 | B12: 0.12334491 | C12: -7.1600158 | D12: 112.78153 | E12: 58.412806 | H12: Referensi Trimble | I12: BM1 | J12: Referensi BM1
A13: 46056 | B13: 0.12335648 | C13: -7.1600158 | D13: 112.78153 | E13: 58.414595 | H13: Mean Trimble Latitude | I13: -7.1600167 | J13: Nilai mean dari file Trimble BM1
A14: 46056 | B14: 0.12336806 | C14: -7.1600158 | D14: 112.78153 | E14: 58.412418 | H14: Mean Trimble Longitude | I14: 112.78153 | J14: Nilai mean dari file Trimble BM1
A15: 46056 | B15: 0.12337963 | C15: -7.1600158 | D15: 112.78153 | E15: 58.414578 | H15: Mean Trimble Height (m) | I15: 58.875071 | J15: Nilai mean dari file Trimble BM1
A16: 46056 | B16: 0.1233912 | C16: -7.1600158 | D16: 112.78153 | E16: 58.413841 | H16: RMSE Latitude vs Trimble | I16: =SQRT(SUMPRODUCT((C2:C2369-$I$13)*(C2:C2369-$I$13))/COUNT(C2:C2369)) -> 6.8039704e-07 | J16: '=SQRT(SUMPRODUCT((C2:C2369-$I$13)*(C2:C2369-$I$13))/COUNT(C2:C2369))
